INFO:pyftpdlib:concurrency model: async
INFO:pyftpdlib:masquerade (NAT) address: 127.0.0.1
INFO:pyftpdlib:passive ports: 60000->65534
DEBUG:pyftpdlib:poller: 'pyftpdlib.ioloop.Kqueue'
DEBUG:pyftpdlib:authorizer: 'ravftp.ftp_server.DummyMD5Authorizer'
DEBUG:pyftpdlib:use sendfile(2): True
DEBUG:pyftpdlib:handler: 'pyftpdlib.handlers.type'
DEBUG:pyftpdlib:max connections: 512
DEBUG:pyftpdlib:max connections per ip: unlimited
DEBUG:pyftpdlib:timeout: 300
DEBUG:pyftpdlib:banner: 'pyftpdlib 1.5.6 ready.'
DEBUG:pyftpdlib:max login attempts: 3
INFO:pyftpdlib:>>> starting FTP server on 0.0.0.0:21, pid=25887 <<<
INFO:pyftpdlib:concurrency model: async
INFO:pyftpdlib:masquerade (NAT) address: 127.0.0.1
INFO:pyftpdlib:passive ports: 60000->65534
DEBUG:pyftpdlib:poller: 'pyftpdlib.ioloop.Kqueue'
DEBUG:pyftpdlib:authorizer: 'ravftp.ftp_server.DummyMD5Authorizer'
DEBUG:pyftpdlib:use sendfile(2): True
DEBUG:pyftpdlib:handler: 'pyftpdlib.handlers.type'
DEBUG:pyftpdlib:max connections: 512
DEBUG:pyftpdlib:max connections per ip: unlimited
DEBUG:pyftpdlib:timeout: 300
DEBUG:pyftpdlib:banner: 'pyftpdlib 1.5.6 ready.'
DEBUG:pyftpdlib:max login attempts: 3
INFO:pyftpdlib:>>> starting FTP server on 0.0.0.0:21, pid=26094 <<<
INFO:werkzeug:127.0.0.1 - - [17/Sep/2022 18:03:10] "GET /add_user?username=1447416226&password=XPDJ87AQ5S HTTP/1.1" 200 -
INFO:pyftpdlib:127.0.0.1:61230-[] FTP session opened (connect)
DEBUG:pyftpdlib:127.0.0.1:61230-[] -> 220 pyftpdlib 1.5.6 ready.
DEBUG:pyftpdlib:127.0.0.1:61230-[] <- USER 1447416226
DEBUG:pyftpdlib:127.0.0.1:61230-[] -> 331 Username ok, send password.
DEBUG:pyftpdlib:127.0.0.1:61230-[1447416226] <- PASS ******
DEBUG:pyftpdlib:127.0.0.1:61230-[] -> 530 Authentication failed.
INFO:pyftpdlib:127.0.0.1:61230-[] USER '1447416226' failed login.
DEBUG:pyftpdlib:[debug] call: close() (<FTPHandler(id=4572751136, addr='127.0.0.1:61230')>)
INFO:pyftpdlib:127.0.0.1:61230-[] FTP session closed (disconnect).
INFO:pyftpdlib:concurrency model: async
INFO:pyftpdlib:masquerade (NAT) address: 127.0.0.1
INFO:pyftpdlib:passive ports: 60000->65534
DEBUG:pyftpdlib:poller: 'pyftpdlib.ioloop.Kqueue'
DEBUG:pyftpdlib:authorizer: 'ravftp.ftp_server.DummyMD5Authorizer'
DEBUG:pyftpdlib:use sendfile(2): True
DEBUG:pyftpdlib:handler: 'pyftpdlib.handlers.type'
DEBUG:pyftpdlib:max connections: 512
DEBUG:pyftpdlib:max connections per ip: unlimited
DEBUG:pyftpdlib:timeout: 300
DEBUG:pyftpdlib:banner: 'pyftpdlib 1.5.6 ready.'
DEBUG:pyftpdlib:max login attempts: 3
INFO:pyftpdlib:>>> starting FTP server on 0.0.0.0:21, pid=26608 <<<
INFO:pyftpdlib:127.0.0.1:61609-[] FTP session opened (connect)
DEBUG:pyftpdlib:127.0.0.1:61609-[] -> 220 pyftpdlib 1.5.6 ready.
DEBUG:pyftpdlib:127.0.0.1:61609-[] <- USER 1447416226
DEBUG:pyftpdlib:127.0.0.1:61609-[] -> 331 Username ok, send password.
DEBUG:pyftpdlib:127.0.0.1:61609-[1447416226] <- PASS ******
DEBUG:pyftpdlib:127.0.0.1:61609-[1447416226] -> 230 Login successful.
INFO:pyftpdlib:127.0.0.1:61609-[1447416226] USER '1447416226' logged in.
DEBUG:pyftpdlib:[debug] call: close() (<FTPHandler(id=4328987328, addr='127.0.0.1:61609', user='1447416226')>)
INFO:pyftpdlib:127.0.0.1:61609-[1447416226] FTP session closed (disconnect).
INFO:pyftpdlib:127.0.0.1:61620-[] FTP session opened (connect)
DEBUG:pyftpdlib:127.0.0.1:61620-[] -> 220 pyftpdlib 1.5.6 ready.
DEBUG:pyftpdlib:127.0.0.1:61620-[] <- USER 1447416226
DEBUG:pyftpdlib:127.0.0.1:61620-[] -> 331 Username ok, send password.
DEBUG:pyftpdlib:127.0.0.1:61620-[1447416226] <- PASS ******
DEBUG:pyftpdlib:127.0.0.1:61620-[1447416226] -> 230 Login successful.
INFO:pyftpdlib:127.0.0.1:61620-[1447416226] USER '1447416226' logged in.
INFO:pyftpdlib:127.0.0.1:61620-[1447416226] -> 421 Control connection timed out.
DEBUG:pyftpdlib:[debug] call: close() (<FTPHandler(id=4328987280, addr='127.0.0.1:61620', user='1447416226')>)
INFO:pyftpdlib:127.0.0.1:61620-[1447416226] FTP session closed (disconnect).
